{
 "cells": [
  {
   "cell_type": "code",
   "execution_count": 1,
   "id": "c7be97e3",
   "metadata": {},
   "outputs": [],
   "source": [
    "from tensorflow.keras.models import Model\n",
    "\n",
    "import tensorflow as tf\n",
    "\n",
    "from tensorflow.python.keras.utils.vis_utils import plot_model\n"
   ]
  },
  {
   "cell_type": "code",
   "execution_count": 6,
   "id": "3d009c22",
   "metadata": {},
   "outputs": [],
   "source": [
    "def base_network(with_input):\n",
    "    \n",
    "    x = tf.keras.layers.Dense(128, activation = tf.nn.relu)(with_input)\n",
    "    x = tf.keras.layers.Dense(20, activation = tf.nn.relu)(x)\n",
    "    return x"
   ]
  },
  {
   "cell_type": "code",
   "execution_count": 11,
   "id": "bd822eec",
   "metadata": {},
   "outputs": [],
   "source": [
    "def build_model():\n",
    "    input_a = tf.keras.Input(shape=(28,28))\n",
    "    input_b = tf.keras.Input(shape=(28, 28))\n",
    "    \n",
    "    vec_output_a = base_network(input_a)\n",
    "    vec_output_b = base_network(input_b)\n",
    "    \n",
    "    output = tf.keras.layers.Lambda(vec_output_a*5)\n",
    "    model = Model(inputs=[input_a, input_b], outputs=output)\n",
    "    return model"
   ]
  },
  {
   "cell_type": "code",
   "execution_count": 12,
   "id": "6cbaca25",
   "metadata": {},
   "outputs": [
    {
     "ename": "TypeError",
     "evalue": "unsupported callable",
     "output_type": "error",
     "traceback": [
      "\u001b[1;31m---------------------------------------------------------------------------\u001b[0m",
      "\u001b[1;31mTypeError\u001b[0m                                 Traceback (most recent call last)",
      "File \u001b[1;32mD:\\Tools\\anaconda3\\envs\\advanTecflow\\lib\\inspect.py:1277\u001b[0m, in \u001b[0;36mgetfullargspec\u001b[1;34m(func)\u001b[0m\n\u001b[0;32m   1260\u001b[0m \u001b[38;5;28;01mtry\u001b[39;00m:\n\u001b[0;32m   1261\u001b[0m     \u001b[38;5;66;03m# Re: `skip_bound_arg=False`\u001b[39;00m\n\u001b[0;32m   1262\u001b[0m     \u001b[38;5;66;03m#\u001b[39;00m\n\u001b[1;32m   (...)\u001b[0m\n\u001b[0;32m   1274\u001b[0m     \u001b[38;5;66;03m# getfullargspec() historically ignored __wrapped__ attributes,\u001b[39;00m\n\u001b[0;32m   1275\u001b[0m     \u001b[38;5;66;03m# so we ensure that remains the case in 3.3+\u001b[39;00m\n\u001b[1;32m-> 1277\u001b[0m     sig \u001b[38;5;241m=\u001b[39m \u001b[43m_signature_from_callable\u001b[49m\u001b[43m(\u001b[49m\u001b[43mfunc\u001b[49m\u001b[43m,\u001b[49m\n\u001b[0;32m   1278\u001b[0m \u001b[43m                                   \u001b[49m\u001b[43mfollow_wrapper_chains\u001b[49m\u001b[38;5;241;43m=\u001b[39;49m\u001b[38;5;28;43;01mFalse\u001b[39;49;00m\u001b[43m,\u001b[49m\n\u001b[0;32m   1279\u001b[0m \u001b[43m                                   \u001b[49m\u001b[43mskip_bound_arg\u001b[49m\u001b[38;5;241;43m=\u001b[39;49m\u001b[38;5;28;43;01mFalse\u001b[39;49;00m\u001b[43m,\u001b[49m\n\u001b[0;32m   1280\u001b[0m \u001b[43m                                   \u001b[49m\u001b[43msigcls\u001b[49m\u001b[38;5;241;43m=\u001b[39;49m\u001b[43mSignature\u001b[49m\u001b[43m,\u001b[49m\n\u001b[0;32m   1281\u001b[0m \u001b[43m                                   \u001b[49m\u001b[43meval_str\u001b[49m\u001b[38;5;241;43m=\u001b[39;49m\u001b[38;5;28;43;01mFalse\u001b[39;49;00m\u001b[43m)\u001b[49m\n\u001b[0;32m   1282\u001b[0m \u001b[38;5;28;01mexcept\u001b[39;00m \u001b[38;5;167;01mException\u001b[39;00m \u001b[38;5;28;01mas\u001b[39;00m ex:\n\u001b[0;32m   1283\u001b[0m     \u001b[38;5;66;03m# Most of the times 'signature' will raise ValueError.\u001b[39;00m\n\u001b[0;32m   1284\u001b[0m     \u001b[38;5;66;03m# But, it can also raise AttributeError, and, maybe something\u001b[39;00m\n\u001b[0;32m   1285\u001b[0m     \u001b[38;5;66;03m# else. So to be fully backwards compatible, we catch all\u001b[39;00m\n\u001b[0;32m   1286\u001b[0m     \u001b[38;5;66;03m# possible exceptions here, and reraise a TypeError.\u001b[39;00m\n",
      "File \u001b[1;32mD:\\Tools\\anaconda3\\envs\\advanTecflow\\lib\\inspect.py:2396\u001b[0m, in \u001b[0;36m_signature_from_callable\u001b[1;34m(obj, follow_wrapper_chains, skip_bound_arg, globals, locals, eval_str, sigcls)\u001b[0m\n\u001b[0;32m   2395\u001b[0m \u001b[38;5;28;01mif\u001b[39;00m \u001b[38;5;129;01mnot\u001b[39;00m callable(obj):\n\u001b[1;32m-> 2396\u001b[0m     \u001b[38;5;28;01mraise\u001b[39;00m \u001b[38;5;167;01mTypeError\u001b[39;00m(\u001b[38;5;124m'\u001b[39m\u001b[38;5;132;01m{!r}\u001b[39;00m\u001b[38;5;124m is not a callable object\u001b[39m\u001b[38;5;124m'\u001b[39m\u001b[38;5;241m.\u001b[39mformat(obj))\n\u001b[0;32m   2398\u001b[0m \u001b[38;5;28;01mif\u001b[39;00m \u001b[38;5;28misinstance\u001b[39m(obj, types\u001b[38;5;241m.\u001b[39mMethodType):\n\u001b[0;32m   2399\u001b[0m     \u001b[38;5;66;03m# In this case we skip the first parameter of the underlying\u001b[39;00m\n\u001b[0;32m   2400\u001b[0m     \u001b[38;5;66;03m# function (usually `self` or `cls`).\u001b[39;00m\n",
      "\u001b[1;31mTypeError\u001b[0m: <KerasTensor: shape=(None, 28, 20) dtype=float32 (created by layer 'tf.math.multiply')> is not a callable object",
      "\nThe above exception was the direct cause of the following exception:\n",
      "\u001b[1;31mTypeError\u001b[0m                                 Traceback (most recent call last)",
      "Cell \u001b[1;32mIn[12], line 1\u001b[0m\n\u001b[1;32m----> 1\u001b[0m model \u001b[38;5;241m=\u001b[39m \u001b[43mbuild_model\u001b[49m\u001b[43m(\u001b[49m\u001b[43m)\u001b[49m\n\u001b[0;32m      3\u001b[0m plot_model(show_shapes\u001b[38;5;241m=\u001b[39m\u001b[38;5;28;01mTrue\u001b[39;00m, show_layer_names\u001b[38;5;241m=\u001b[39m\u001b[38;5;28;01mTrue\u001b[39;00m, to_file\u001b[38;5;241m=\u001b[39m\u001b[38;5;124m\"\u001b[39m\u001b[38;5;124mmodel.png\u001b[39m\u001b[38;5;124m\"\u001b[39m)\n",
      "Cell \u001b[1;32mIn[11], line 8\u001b[0m, in \u001b[0;36mbuild_model\u001b[1;34m()\u001b[0m\n\u001b[0;32m      5\u001b[0m vec_output_a \u001b[38;5;241m=\u001b[39m base_network(input_a)\n\u001b[0;32m      6\u001b[0m vec_output_b \u001b[38;5;241m=\u001b[39m base_network(input_b)\n\u001b[1;32m----> 8\u001b[0m output \u001b[38;5;241m=\u001b[39m \u001b[43mtf\u001b[49m\u001b[38;5;241;43m.\u001b[39;49m\u001b[43mkeras\u001b[49m\u001b[38;5;241;43m.\u001b[39;49m\u001b[43mlayers\u001b[49m\u001b[38;5;241;43m.\u001b[39;49m\u001b[43mLambda\u001b[49m\u001b[43m(\u001b[49m\u001b[43mvec_output_a\u001b[49m\u001b[38;5;241;43m*\u001b[39;49m\u001b[38;5;241;43m5\u001b[39;49m\u001b[43m)\u001b[49m\n\u001b[0;32m      9\u001b[0m model \u001b[38;5;241m=\u001b[39m Model(inputs\u001b[38;5;241m=\u001b[39m[input_a, input_b], outputs\u001b[38;5;241m=\u001b[39moutput)\n\u001b[0;32m     10\u001b[0m \u001b[38;5;28;01mreturn\u001b[39;00m model\n",
      "File \u001b[1;32mD:\\Tools\\anaconda3\\envs\\advanTecflow\\lib\\site-packages\\tensorflow\\python\\trackable\\base.py:205\u001b[0m, in \u001b[0;36mno_automatic_dependency_tracking.<locals>._method_wrapper\u001b[1;34m(self, *args, **kwargs)\u001b[0m\n\u001b[0;32m    203\u001b[0m \u001b[38;5;28mself\u001b[39m\u001b[38;5;241m.\u001b[39m_self_setattr_tracking \u001b[38;5;241m=\u001b[39m \u001b[38;5;28;01mFalse\u001b[39;00m  \u001b[38;5;66;03m# pylint: disable=protected-access\u001b[39;00m\n\u001b[0;32m    204\u001b[0m \u001b[38;5;28;01mtry\u001b[39;00m:\n\u001b[1;32m--> 205\u001b[0m   result \u001b[38;5;241m=\u001b[39m method(\u001b[38;5;28mself\u001b[39m, \u001b[38;5;241m*\u001b[39margs, \u001b[38;5;241m*\u001b[39m\u001b[38;5;241m*\u001b[39mkwargs)\n\u001b[0;32m    206\u001b[0m \u001b[38;5;28;01mfinally\u001b[39;00m:\n\u001b[0;32m    207\u001b[0m   \u001b[38;5;28mself\u001b[39m\u001b[38;5;241m.\u001b[39m_self_setattr_tracking \u001b[38;5;241m=\u001b[39m previous_value  \u001b[38;5;66;03m# pylint: disable=protected-access\u001b[39;00m\n",
      "File \u001b[1;32mD:\\Tools\\anaconda3\\envs\\advanTecflow\\lib\\site-packages\\keras\\layers\\core\\lambda_layer.py:150\u001b[0m, in \u001b[0;36mLambda.__init__\u001b[1;34m(self, function, output_shape, mask, arguments, **kwargs)\u001b[0m\n\u001b[0;32m    147\u001b[0m \u001b[38;5;66;03m# Warning on every invocation will be quite irksome in Eager mode.\u001b[39;00m\n\u001b[0;32m    148\u001b[0m \u001b[38;5;28mself\u001b[39m\u001b[38;5;241m.\u001b[39m_already_warned \u001b[38;5;241m=\u001b[39m \u001b[38;5;28;01mFalse\u001b[39;00m\n\u001b[1;32m--> 150\u001b[0m function_args \u001b[38;5;241m=\u001b[39m \u001b[43mtf_inspect\u001b[49m\u001b[38;5;241;43m.\u001b[39;49m\u001b[43mgetfullargspec\u001b[49m\u001b[43m(\u001b[49m\u001b[43mfunction\u001b[49m\u001b[43m)\u001b[49m\u001b[38;5;241m.\u001b[39margs\n\u001b[0;32m    151\u001b[0m \u001b[38;5;28mself\u001b[39m\u001b[38;5;241m.\u001b[39m_fn_expects_training_arg \u001b[38;5;241m=\u001b[39m \u001b[38;5;124m\"\u001b[39m\u001b[38;5;124mtraining\u001b[39m\u001b[38;5;124m\"\u001b[39m \u001b[38;5;129;01min\u001b[39;00m function_args\n\u001b[0;32m    152\u001b[0m \u001b[38;5;28mself\u001b[39m\u001b[38;5;241m.\u001b[39m_fn_expects_mask_arg \u001b[38;5;241m=\u001b[39m \u001b[38;5;124m\"\u001b[39m\u001b[38;5;124mmask\u001b[39m\u001b[38;5;124m\"\u001b[39m \u001b[38;5;129;01min\u001b[39;00m function_args\n",
      "File \u001b[1;32mD:\\Tools\\anaconda3\\envs\\advanTecflow\\lib\\site-packages\\keras\\utils\\tf_inspect.py:286\u001b[0m, in \u001b[0;36mgetfullargspec\u001b[1;34m(obj)\u001b[0m\n\u001b[0;32m    284\u001b[0m     \u001b[38;5;28;01mif\u001b[39;00m d\u001b[38;5;241m.\u001b[39mdecorator_argspec \u001b[38;5;129;01mis\u001b[39;00m \u001b[38;5;129;01mnot\u001b[39;00m \u001b[38;5;28;01mNone\u001b[39;00m:\n\u001b[0;32m    285\u001b[0m         \u001b[38;5;28;01mreturn\u001b[39;00m _convert_maybe_argspec_to_fullargspec(d\u001b[38;5;241m.\u001b[39mdecorator_argspec)\n\u001b[1;32m--> 286\u001b[0m \u001b[38;5;28;01mreturn\u001b[39;00m \u001b[43m_getfullargspec\u001b[49m\u001b[43m(\u001b[49m\u001b[43mtarget\u001b[49m\u001b[43m)\u001b[49m\n",
      "File \u001b[1;32mD:\\Tools\\anaconda3\\envs\\advanTecflow\\lib\\inspect.py:1287\u001b[0m, in \u001b[0;36mgetfullargspec\u001b[1;34m(func)\u001b[0m\n\u001b[0;32m   1277\u001b[0m     sig \u001b[38;5;241m=\u001b[39m _signature_from_callable(func,\n\u001b[0;32m   1278\u001b[0m                                    follow_wrapper_chains\u001b[38;5;241m=\u001b[39m\u001b[38;5;28;01mFalse\u001b[39;00m,\n\u001b[0;32m   1279\u001b[0m                                    skip_bound_arg\u001b[38;5;241m=\u001b[39m\u001b[38;5;28;01mFalse\u001b[39;00m,\n\u001b[0;32m   1280\u001b[0m                                    sigcls\u001b[38;5;241m=\u001b[39mSignature,\n\u001b[0;32m   1281\u001b[0m                                    eval_str\u001b[38;5;241m=\u001b[39m\u001b[38;5;28;01mFalse\u001b[39;00m)\n\u001b[0;32m   1282\u001b[0m \u001b[38;5;28;01mexcept\u001b[39;00m \u001b[38;5;167;01mException\u001b[39;00m \u001b[38;5;28;01mas\u001b[39;00m ex:\n\u001b[0;32m   1283\u001b[0m     \u001b[38;5;66;03m# Most of the times 'signature' will raise ValueError.\u001b[39;00m\n\u001b[0;32m   1284\u001b[0m     \u001b[38;5;66;03m# But, it can also raise AttributeError, and, maybe something\u001b[39;00m\n\u001b[0;32m   1285\u001b[0m     \u001b[38;5;66;03m# else. So to be fully backwards compatible, we catch all\u001b[39;00m\n\u001b[0;32m   1286\u001b[0m     \u001b[38;5;66;03m# possible exceptions here, and reraise a TypeError.\u001b[39;00m\n\u001b[1;32m-> 1287\u001b[0m     \u001b[38;5;28;01mraise\u001b[39;00m \u001b[38;5;167;01mTypeError\u001b[39;00m(\u001b[38;5;124m'\u001b[39m\u001b[38;5;124munsupported callable\u001b[39m\u001b[38;5;124m'\u001b[39m) \u001b[38;5;28;01mfrom\u001b[39;00m \u001b[38;5;21;01mex\u001b[39;00m\n\u001b[0;32m   1289\u001b[0m args \u001b[38;5;241m=\u001b[39m []\n\u001b[0;32m   1290\u001b[0m varargs \u001b[38;5;241m=\u001b[39m \u001b[38;5;28;01mNone\u001b[39;00m\n",
      "\u001b[1;31mTypeError\u001b[0m: unsupported callable"
     ]
    }
   ],
   "source": [
    "model = build_model()\n",
    "\n",
    "plot_model(show_shapes=True, show_layer_names=True, to_file=\"model.png\")"
   ]
  },
  {
   "cell_type": "code",
   "execution_count": null,
   "id": "abb32e05",
   "metadata": {},
   "outputs": [],
   "source": []
  }
 ],
 "metadata": {
  "kernelspec": {
   "display_name": "Python 3 (ipykernel)",
   "language": "python",
   "name": "python3"
  },
  "language_info": {
   "codemirror_mode": {
    "name": "ipython",
    "version": 3
   },
   "file_extension": ".py",
   "mimetype": "text/x-python",
   "name": "python",
   "nbconvert_exporter": "python",
   "pygments_lexer": "ipython3",
   "version": "3.10.11"
  }
 },
 "nbformat": 4,
 "nbformat_minor": 5
}
